{
 "cells": [
  {
   "cell_type": "code",
   "execution_count": 2,
   "metadata": {},
   "outputs": [],
   "source": [
    "import os"
   ]
  },
  {
   "cell_type": "code",
   "execution_count": 3,
   "metadata": {},
   "outputs": [
    {
     "data": {
      "text/plain": [
       "'c:\\\\Users\\\\HP\\\\project\\\\kideny_disease_classification\\\\research'"
      ]
     },
     "execution_count": 3,
     "metadata": {},
     "output_type": "execute_result"
    }
   ],
   "source": [
    "%pwd"
   ]
  },
  {
   "cell_type": "code",
   "execution_count": 4,
   "metadata": {},
   "outputs": [],
   "source": [
    "os.chdir('../')"
   ]
  },
  {
   "cell_type": "code",
   "execution_count": 5,
   "metadata": {},
   "outputs": [
    {
     "data": {
      "text/plain": [
       "'c:\\\\Users\\\\HP\\\\project\\\\kideny_disease_classification'"
      ]
     },
     "execution_count": 5,
     "metadata": {},
     "output_type": "execute_result"
    }
   ],
   "source": [
    "%pwd"
   ]
  },
  {
   "cell_type": "code",
   "execution_count": 6,
   "metadata": {},
   "outputs": [],
   "source": [
    "from dataclasses import dataclass\n",
    "from pathlib import Path\n",
    "\n",
    "@dataclass(frozen=True)\n",
    "class DataIngestionConfig:\n",
    "    root_dir: Path\n",
    "    source_URL: str\n",
    "    local_data_file: Path\n",
    "    unzip_dir: Path"
   ]
  },
  {
   "cell_type": "code",
   "execution_count": 7,
   "metadata": {},
   "outputs": [],
   "source": [
    "from cnnClassifier.constants import *\n",
    "from cnnClassifier.utils.common import read_yaml, create_directories\n"
   ]
  },
  {
   "cell_type": "code",
   "execution_count": 8,
   "metadata": {},
   "outputs": [],
   "source": [
    "class configurationManager:\n",
    "    def __init__(self,\n",
    "                 config_filepath= CONFIG_FILE_PATH,\n",
    "                 params_filepath=PARAMS_FILE_PATH ):\n",
    "        self.config = read_yaml(config_filepath)\n",
    "        self.params = read_yaml(params_filepath)\n",
    "\n",
    "        create_directories([self.config.artifacts_root])\n",
    "\n",
    "    def get_data_ingestion_config(self) -> DataIngestionConfig:\n",
    "        config = self.config.data_ingestion\n",
    "\n",
    "        create_directories([config.root_dir])\n",
    "\n",
    "        data_ingestion_config = DataIngestionConfig(\n",
    "            root_dir=config.root_dir,\n",
    "            source_URL= config.source_file,\n",
    "            local_data_file=config.local_data_file,\n",
    "            unzip_dir=config.unzip_dir\n",
    "        )\n",
    "\n",
    "        return data_ingestion_config\n"
   ]
  },
  {
   "cell_type": "code",
   "execution_count": 9,
   "metadata": {},
   "outputs": [],
   "source": [
    "import os\n",
    "import zipfile\n",
    "import gdown\n",
    "from cnnClassifier import logger\n",
    "from cnnClassifier.utils.common import get_size"
   ]
  },
  {
   "cell_type": "code",
   "execution_count": 10,
   "metadata": {},
   "outputs": [],
   "source": [
    "class DataIngestion:\n",
    "    def __init__(self, config: DataIngestionConfig):\n",
    "        self.config = config\n",
    "\n",
    "    def download_file(self) -> str:\n",
    "        \"\"\"featch the data from the url\"\"\"\n",
    "\n",
    "        try:\n",
    "            dataset_url = self.config.source_URL\n",
    "            zip_download_dir = self.config.local_data_file\n",
    "            os.makedirs(\"artifacts/data_ingestion\",exist_ok=True)\n",
    "            logger.info(f\"downloading data from {dataset_url} into file {zip_download_dir}\")\n",
    "\n",
    "            file_id = dataset_url.split(\"/\")[-2]\n",
    "            prefix = 'https://drive.google.com/uc?/export=download&id='\n",
    "            gdown.download(prefix+file_id, zip_download_dir)\n",
    "\n",
    "            logger.info(f\"Downloaded data from {dataset_url} into file {zip_download_dir}\")\n",
    "        except Exception as e:\n",
    "            raise e\n",
    "        \n",
    "\n",
    "    def extract_zip_file(self):\n",
    "        \"\"\"\n",
    "        zip_file_path: str\n",
    "        extract the zip file into data directory\n",
    "        function return None\n",
    "        \"\"\"\n",
    "        unzip_path = self.config.unzip_dir\n",
    "        os.makedirs(unzip_path, exist_ok=True)\n",
    "        with zipfile.ZipFile(self.config.local_data_file,'r') as zip_ref:\n",
    "            zip_ref.extractall(unzip_path)"
   ]
  },
  {
   "cell_type": "code",
   "execution_count": 11,
   "metadata": {},
   "outputs": [
    {
     "name": "stdout",
     "output_type": "stream",
     "text": [
      "[2024-09-20 09:59:23,896: INFO: common: yaml file: config\\config.yaml loaded successfully]\n",
      "[2024-09-20 09:59:23,906: INFO: common: yaml file: params.yaml loaded successfully]\n",
      "[2024-09-20 09:59:23,909: INFO: common: created directory at: artifacts]\n",
      "[2024-09-20 09:59:23,910: INFO: common: created directory at: artifacts/data_ingestion]\n"
     ]
    },
    {
     "ename": "BoxKeyError",
     "evalue": "\"'ConfigBox' object has no attribute 'source_url'\"",
     "output_type": "error",
     "traceback": [
      "\u001b[1;31m---------------------------------------------------------------------------\u001b[0m",
      "\u001b[1;31mKeyError\u001b[0m                                  Traceback (most recent call last)",
      "File \u001b[1;32mc:\\Users\\HP\\anaconda3\\envs\\kideny\\lib\\site-packages\\box\\box.py:593\u001b[0m, in \u001b[0;36mbox.box.Box.__getitem__\u001b[1;34m()\u001b[0m\n",
      "\u001b[1;31mKeyError\u001b[0m: 'source_URL'",
      "\nThe above exception was the direct cause of the following exception:\n",
      "\u001b[1;31mBoxKeyError\u001b[0m                               Traceback (most recent call last)",
      "File \u001b[1;32mc:\\Users\\HP\\anaconda3\\envs\\kideny\\lib\\site-packages\\box\\box.py:632\u001b[0m, in \u001b[0;36mbox.box.Box.__getattr__\u001b[1;34m()\u001b[0m\n",
      "File \u001b[1;32mc:\\Users\\HP\\anaconda3\\envs\\kideny\\lib\\site-packages\\box\\box.py:620\u001b[0m, in \u001b[0;36mbox.box.Box.__getitem__\u001b[1;34m()\u001b[0m\n",
      "\u001b[1;31mBoxKeyError\u001b[0m: \"'source_URL'\"",
      "\nDuring handling of the above exception, another exception occurred:\n",
      "\u001b[1;31mAttributeError\u001b[0m                            Traceback (most recent call last)",
      "File \u001b[1;32mc:\\Users\\HP\\anaconda3\\envs\\kideny\\lib\\site-packages\\box\\box.py:634\u001b[0m, in \u001b[0;36mbox.box.Box.__getattr__\u001b[1;34m()\u001b[0m\n",
      "\u001b[1;31mAttributeError\u001b[0m: 'ConfigBox' object has no attribute 'source_URL'",
      "\nThe above exception was the direct cause of the following exception:\n",
      "\u001b[1;31mBoxKeyError\u001b[0m                               Traceback (most recent call last)",
      "File \u001b[1;32mc:\\Users\\HP\\anaconda3\\envs\\kideny\\lib\\site-packages\\box\\config_box.py:29\u001b[0m, in \u001b[0;36mbox.config_box.ConfigBox.__getattr__\u001b[1;34m()\u001b[0m\n",
      "File \u001b[1;32mc:\\Users\\HP\\anaconda3\\envs\\kideny\\lib\\site-packages\\box\\box.py:648\u001b[0m, in \u001b[0;36mbox.box.Box.__getattr__\u001b[1;34m()\u001b[0m\n",
      "\u001b[1;31mBoxKeyError\u001b[0m: \"'ConfigBox' object has no attribute 'source_URL'\"",
      "\nDuring handling of the above exception, another exception occurred:\n",
      "\u001b[1;31mKeyError\u001b[0m                                  Traceback (most recent call last)",
      "File \u001b[1;32mc:\\Users\\HP\\anaconda3\\envs\\kideny\\lib\\site-packages\\box\\box.py:593\u001b[0m, in \u001b[0;36mbox.box.Box.__getitem__\u001b[1;34m()\u001b[0m\n",
      "\u001b[1;31mKeyError\u001b[0m: 'source_url'",
      "\nThe above exception was the direct cause of the following exception:\n",
      "\u001b[1;31mBoxKeyError\u001b[0m                               Traceback (most recent call last)",
      "File \u001b[1;32mc:\\Users\\HP\\anaconda3\\envs\\kideny\\lib\\site-packages\\box\\box.py:632\u001b[0m, in \u001b[0;36mbox.box.Box.__getattr__\u001b[1;34m()\u001b[0m\n",
      "File \u001b[1;32mc:\\Users\\HP\\anaconda3\\envs\\kideny\\lib\\site-packages\\box\\box.py:620\u001b[0m, in \u001b[0;36mbox.box.Box.__getitem__\u001b[1;34m()\u001b[0m\n",
      "\u001b[1;31mBoxKeyError\u001b[0m: \"'source_url'\"",
      "\nDuring handling of the above exception, another exception occurred:\n",
      "\u001b[1;31mAttributeError\u001b[0m                            Traceback (most recent call last)",
      "File \u001b[1;32mc:\\Users\\HP\\anaconda3\\envs\\kideny\\lib\\site-packages\\box\\box.py:634\u001b[0m, in \u001b[0;36mbox.box.Box.__getattr__\u001b[1;34m()\u001b[0m\n",
      "\u001b[1;31mAttributeError\u001b[0m: 'ConfigBox' object has no attribute 'source_url'",
      "\nThe above exception was the direct cause of the following exception:\n",
      "\u001b[1;31mBoxKeyError\u001b[0m                               Traceback (most recent call last)",
      "Cell \u001b[1;32mIn[11], line 8\u001b[0m\n\u001b[0;32m      6\u001b[0m     data_ingestion\u001b[38;5;241m.\u001b[39mextract_zip_file()\n\u001b[0;32m      7\u001b[0m \u001b[38;5;28;01mexcept\u001b[39;00m \u001b[38;5;167;01mException\u001b[39;00m \u001b[38;5;28;01mas\u001b[39;00m e:\n\u001b[1;32m----> 8\u001b[0m     \u001b[38;5;28;01mraise\u001b[39;00m e\n",
      "Cell \u001b[1;32mIn[11], line 3\u001b[0m\n\u001b[0;32m      1\u001b[0m \u001b[38;5;28;01mtry\u001b[39;00m:\n\u001b[0;32m      2\u001b[0m     config \u001b[38;5;241m=\u001b[39m configurationManager()\n\u001b[1;32m----> 3\u001b[0m     data_ingestion_config \u001b[38;5;241m=\u001b[39m \u001b[43mconfig\u001b[49m\u001b[38;5;241;43m.\u001b[39;49m\u001b[43mget_data_ingestion_config\u001b[49m\u001b[43m(\u001b[49m\u001b[43m)\u001b[49m\n\u001b[0;32m      4\u001b[0m     data_ingestion \u001b[38;5;241m=\u001b[39m DataIngestion(config\u001b[38;5;241m=\u001b[39mdata_ingestion_config)\n\u001b[0;32m      5\u001b[0m     data_ingestion\u001b[38;5;241m.\u001b[39mdownload_file()\n",
      "Cell \u001b[1;32mIn[8], line 17\u001b[0m, in \u001b[0;36mconfigurationManager.get_data_ingestion_config\u001b[1;34m(self)\u001b[0m\n\u001b[0;32m     11\u001b[0m config \u001b[38;5;241m=\u001b[39m \u001b[38;5;28mself\u001b[39m\u001b[38;5;241m.\u001b[39mconfig\u001b[38;5;241m.\u001b[39mdata_ingestion\n\u001b[0;32m     13\u001b[0m create_directories([config\u001b[38;5;241m.\u001b[39mroot_dir])\n\u001b[0;32m     15\u001b[0m data_ingestion_config \u001b[38;5;241m=\u001b[39m DataIngestionConfig(\n\u001b[0;32m     16\u001b[0m     root_dir\u001b[38;5;241m=\u001b[39mconfig\u001b[38;5;241m.\u001b[39mroot_dir,\n\u001b[1;32m---> 17\u001b[0m     source_URL\u001b[38;5;241m=\u001b[39m \u001b[43mconfig\u001b[49m\u001b[38;5;241;43m.\u001b[39;49m\u001b[43msource_URL\u001b[49m,\n\u001b[0;32m     18\u001b[0m     local_data_file\u001b[38;5;241m=\u001b[39mconfig\u001b[38;5;241m.\u001b[39mlocal_data_file,\n\u001b[0;32m     19\u001b[0m     unzip_dir\u001b[38;5;241m=\u001b[39mconfig\u001b[38;5;241m.\u001b[39munzip_dir\n\u001b[0;32m     20\u001b[0m )\n\u001b[0;32m     22\u001b[0m \u001b[38;5;28;01mreturn\u001b[39;00m data_ingestion_config\n",
      "File \u001b[1;32mc:\\Users\\HP\\anaconda3\\envs\\kideny\\lib\\site-packages\\box\\config_box.py:31\u001b[0m, in \u001b[0;36mbox.config_box.ConfigBox.__getattr__\u001b[1;34m()\u001b[0m\n",
      "File \u001b[1;32mc:\\Users\\HP\\anaconda3\\envs\\kideny\\lib\\site-packages\\box\\box.py:648\u001b[0m, in \u001b[0;36mbox.box.Box.__getattr__\u001b[1;34m()\u001b[0m\n",
      "\u001b[1;31mBoxKeyError\u001b[0m: \"'ConfigBox' object has no attribute 'source_url'\""
     ]
    }
   ],
   "source": [
    "try:\n",
    "    config = configurationManager()\n",
    "    data_ingestion_config = config.get_data_ingestion_config()\n",
    "    data_ingestion = DataIngestion(config=data_ingestion_config)\n",
    "    data_ingestion.download_file()\n",
    "    data_ingestion.extract_zip_file()\n",
    "except Exception as e:\n",
    "    raise e"
   ]
  }
 ],
 "metadata": {
  "kernelspec": {
   "display_name": "kideny",
   "language": "python",
   "name": "python3"
  },
  "language_info": {
   "codemirror_mode": {
    "name": "ipython",
    "version": 3
   },
   "file_extension": ".py",
   "mimetype": "text/x-python",
   "name": "python",
   "nbconvert_exporter": "python",
   "pygments_lexer": "ipython3",
   "version": "3.10.0"
  }
 },
 "nbformat": 4,
 "nbformat_minor": 2
}
